<?xml version="1.0" ?>
<!-- =================================================================================== -->
<!-- |    This document was autogenerated by xacro from urdf/conbime_ver1.xacro        | -->
<!-- |    EDITING THIS FILE BY HAND IS NOT RECOMMENDED                                 | -->
<!-- =================================================================================== -->
<robot xmlns:xacro="http://www.ros.org/wiki/xacro" name="conbime_ver1">
  <material name="silver">
    <color rgba="0.700 0.700 0.700 1.000"/>
  </material>
  <transmission name="Revolute 1_tran">
    <type>transmission_interface/SimpleTransmission</type>
    <joint name="Revolute 1">
      <hardwareInterface>hardware_interface/EffortJointInterface</hardwareInterface>
    </joint>
    <actuator name="Revolute 1_actr">
      <hardwareInterface>hardware_interface/EffortJointInterface</hardwareInterface>
      <mechanicalReduction>1</mechanicalReduction>
    </actuator>
  </transmission>
  <transmission name="Revolute 2_tran">
    <type>transmission_interface/SimpleTransmission</type>
    <joint name="Revolute 2">
      <hardwareInterface>hardware_interface/EffortJointInterface</hardwareInterface>
    </joint>
    <actuator name="Revolute 2_actr">
      <hardwareInterface>hardware_interface/EffortJointInterface</hardwareInterface>
      <mechanicalReduction>1</mechanicalReduction>
    </actuator>
  </transmission>
  <transmission name="Revolute 3_tran">
    <type>transmission_interface/SimpleTransmission</type>
    <joint name="Revolute 3">
      <hardwareInterface>hardware_interface/EffortJointInterface</hardwareInterface>
    </joint>
    <actuator name="Revolute 3_actr">
      <hardwareInterface>hardware_interface/EffortJointInterface</hardwareInterface>
      <mechanicalReduction>1</mechanicalReduction>
    </actuator>
  </transmission>
  <transmission name="Revolute 5_tran">
    <type>transmission_interface/SimpleTransmission</type>
    <joint name="Revolute 5">
      <hardwareInterface>hardware_interface/EffortJointInterface</hardwareInterface>
    </joint>
    <actuator name="Revolute 5_actr">
      <hardwareInterface>hardware_interface/EffortJointInterface</hardwareInterface>
      <mechanicalReduction>1</mechanicalReduction>
    </actuator>
  </transmission>
  <transmission name="Revolute 6_tran">
    <type>transmission_interface/SimpleTransmission</type>
    <joint name="Revolute 6">
      <hardwareInterface>hardware_interface/EffortJointInterface</hardwareInterface>
    </joint>
    <actuator name="Revolute 6_actr">
      <hardwareInterface>hardware_interface/EffortJointInterface</hardwareInterface>
      <mechanicalReduction>1</mechanicalReduction>
    </actuator>
  </transmission>
  <transmission name="Revolute 7_tran">
    <type>transmission_interface/SimpleTransmission</type>
    <joint name="Revolute 7">
      <hardwareInterface>hardware_interface/EffortJointInterface</hardwareInterface>
    </joint>
    <actuator name="Revolute 7_actr">
      <hardwareInterface>hardware_interface/EffortJointInterface</hardwareInterface>
      <mechanicalReduction>1</mechanicalReduction>
    </actuator>
  </transmission>
  <transmission name="Revolute 10_tran">
    <type>transmission_interface/SimpleTransmission</type>
    <joint name="Revolute 10">
      <hardwareInterface>hardware_interface/EffortJointInterface</hardwareInterface>
    </joint>
    <actuator name="Revolute 10_actr">
      <hardwareInterface>hardware_interface/EffortJointInterface</hardwareInterface>
      <mechanicalReduction>1</mechanicalReduction>
    </actuator>
  </transmission>
  <transmission name="Revolute 11_tran">
    <type>transmission_interface/SimpleTransmission</type>
    <joint name="Revolute 11">
      <hardwareInterface>hardware_interface/EffortJointInterface</hardwareInterface>
    </joint>
    <actuator name="Revolute 11_actr">
      <hardwareInterface>hardware_interface/EffortJointInterface</hardwareInterface>
      <mechanicalReduction>1</mechanicalReduction>
    </actuator>
  </transmission>
  <gazebo>
    <plugin name="control" filename="libgazebo_ros_control.so"/>
  </gazebo>
  <gazebo reference="base_link">
    <material>Gazebo/Silver</material>
    <mu1>0.2</mu1>
    <mu2>0.2</mu2>
    <selfCollide>true</selfCollide>
    <gravity>true</gravity>
  </gazebo>
  <gazebo reference="Robotic_Arm_ver1_2urdf_Component2_v1_1">
    <material>Gazebo/Silver</material>
    <mu1>0.2</mu1>
    <mu2>0.2</mu2>
    <selfCollide>true</selfCollide>
  </gazebo>
  <gazebo reference="Robotic_Arm_ver1_2urdf_Component3_v1_1">
    <material>Gazebo/Silver</material>
    <mu1>0.2</mu1>
    <mu2>0.2</mu2>
    <selfCollide>true</selfCollide>
  </gazebo>
  <gazebo reference="Robotic_Arm_ver1_2urdf_Component4_v1_1">
    <material>Gazebo/Silver</material>
    <mu1>0.2</mu1>
    <mu2>0.2</mu2>
    <selfCollide>true</selfCollide>
  </gazebo>
  <gazebo reference="Robotic_Arm_ver1_2urdf_Component5_v1_1">
    <material>Gazebo/Silver</material>
    <mu1>0.2</mu1>
    <mu2>0.2</mu2>
    <selfCollide>true</selfCollide>
  </gazebo>
  <gazebo reference="Robotic_Arm_ver1_2urdf_Component6_v1_1">
    <material>Gazebo/Silver</material>
    <mu1>0.2</mu1>
    <mu2>0.2</mu2>
    <selfCollide>true</selfCollide>
  </gazebo>
  <gazebo reference="Robotic_Arm_ver1_2urdf_Component7_v1_1">
    <material>Gazebo/Silver</material>
    <mu1>0.2</mu1>
    <mu2>0.2</mu2>
    <selfCollide>true</selfCollide>
  </gazebo>
  <gazebo reference="Robotic_Arm_ver1_2urdf_Component8_v1_1">
    <material>Gazebo/Silver</material>
    <mu1>0.2</mu1>
    <mu2>0.2</mu2>
    <selfCollide>true</selfCollide>
  </gazebo>
  <gazebo reference="Robotic_Arm_ver1_2urdf_Component8_v1__1__1">
    <material>Gazebo/Silver</material>
    <mu1>0.2</mu1>
    <mu2>0.2</mu2>
    <selfCollide>true</selfCollide>
  </gazebo>
  <link name="base_link">
    <inertial>
      <origin xyz="0.0007806396519895977 -0.0007806396451176688 0.048593515527982106" rpy="0 0 0"/>
      <mass value="12.473677758806172"/>
      <inertia ixx="0.118752" iyy="0.118752" izz="0.218412" ixy="0.000272" iyz="-0.000713" ixz="0.000713"/>
    </inertial>
    <visual>
      <origin xyz="0 0 0" rpy="0 0 0"/>
      <geometry>
        <mesh filename="package://conbime_ver1_description/meshes/base_link.stl" scale="0.001 0.001 0.001"/>
      </geometry>
      <material name="silver"/>
    </visual>
    <collision>
      <origin xyz="0 0 0" rpy="0 0 0"/>
      <geometry>
        <mesh filename="package://conbime_ver1_description/meshes/base_link.stl" scale="0.001 0.001 0.001"/>
      </geometry>
    </collision>
  </link>
  <link name="Robotic_Arm_ver1_2urdf_Component2_v1_1">
    <inertial>
      <origin xyz="-0.056861586080370785 -0.002799253146421256 0.072902279125296" rpy="0 0 0"/>
      <mass value="18.09836147401845"/>
      <inertia ixx="0.09336" iyy="0.186513" izz="0.127406" ixy="-0.003762" iyz="0.003286" ixz="0.071121"/>
    </inertial>
    <visual>
      <origin xyz="-0.0 -0.0 -0.104" rpy="0 0 0"/>
      <geometry>
        <mesh filename="package://conbime_ver1_description/meshes/Robotic_Arm_ver1_2urdf_Component2_v1_1.stl" scale="0.001 0.001 0.001"/>
      </geometry>
      <material name="silver"/>
    </visual>
    <collision>
      <origin xyz="-0.0 -0.0 -0.104" rpy="0 0 0"/>
      <geometry>
        <mesh filename="package://conbime_ver1_description/meshes/Robotic_Arm_ver1_2urdf_Component2_v1_1.stl" scale="0.001 0.001 0.001"/>
      </geometry>
    </collision>
  </link>
  <link name="Robotic_Arm_ver1_2urdf_Component3_v1_1">
    <inertial>
      <origin xyz="0.07519560671235662 0.035272202867928204 0.11434064250837306" rpy="0 0 0"/>
      <mass value="6.899811543127018"/>
      <inertia ixx="0.09868" iyy="0.134098" izz="0.037409" ixy="0.000582" iyz="0.000608" ixz="-0.055788"/>
    </inertial>
    <visual>
      <origin xyz="0.15 -0.0 -0.254" rpy="0 0 0"/>
      <geometry>
        <mesh filename="package://conbime_ver1_description/meshes/Robotic_Arm_ver1_2urdf_Component3_v1_1.stl" scale="0.001 0.001 0.001"/>
      </geometry>
      <material name="silver"/>
    </visual>
    <collision>
      <origin xyz="0.15 -0.0 -0.254" rpy="0 0 0"/>
      <geometry>
        <mesh filename="package://conbime_ver1_description/meshes/Robotic_Arm_ver1_2urdf_Component3_v1_1.stl" scale="0.001 0.001 0.001"/>
      </geometry>
    </collision>
  </link>
  <link name="Robotic_Arm_ver1_2urdf_Component4_v1_1">
    <inertial>
      <origin xyz="-0.03544557690535207 -0.02504426465095886 0.038926916052581695" rpy="0 0 0"/>
      <mass value="9.992708750642434"/>
      <inertia ixx="0.01335" iyy="0.051348" izz="0.048383" ixy="-0.000664" iyz="0.000865" ixz="0.002152"/>
    </inertial>
    <visual>
      <origin xyz="-0.025 -0.0 -0.557109" rpy="0 0 0"/>
      <geometry>
        <mesh filename="package://conbime_ver1_description/meshes/Robotic_Arm_ver1_2urdf_Component4_v1_1.stl" scale="0.001 0.001 0.001"/>
      </geometry>
      <material name="silver"/>
    </visual>
    <collision>
      <origin xyz="-0.025 -0.0 -0.557109" rpy="0 0 0"/>
      <geometry>
        <mesh filename="package://conbime_ver1_description/meshes/Robotic_Arm_ver1_2urdf_Component4_v1_1.stl" scale="0.001 0.001 0.001"/>
      </geometry>
    </collision>
  </link>
  <link name="Robotic_Arm_ver1_2urdf_Component5_v1_1">
    <inertial>
      <origin xyz="-0.09983507706433631 9.234350483583453e-08 -9.146592294673184e-08" rpy="0 0 0"/>
      <mass value="4.896549506749971"/>
      <inertia ixx="0.004578" iyy="0.01561" izz="0.0169" ixy="-0.0" iyz="-0.000114" ixz="0.0"/>
    </inertial>
    <visual>
      <origin xyz="0.176 0.026956 -0.602109" rpy="0 0 0"/>
      <geometry>
        <mesh filename="package://conbime_ver1_description/meshes/Robotic_Arm_ver1_2urdf_Component5_v1_1.stl" scale="0.001 0.001 0.001"/>
      </geometry>
      <material name="silver"/>
    </visual>
    <collision>
      <origin xyz="0.176 0.026956 -0.602109" rpy="0 0 0"/>
      <geometry>
        <mesh filename="package://conbime_ver1_description/meshes/Robotic_Arm_ver1_2urdf_Component5_v1_1.stl" scale="0.001 0.001 0.001"/>
      </geometry>
    </collision>
  </link>
  <link name="Robotic_Arm_ver1_2urdf_Component6_v1_1">
    <inertial>
      <origin xyz="-0.05967268352428523 1.0724235042364194e-07 -1.0867544730785994e-07" rpy="0 0 0"/>
      <mass value="2.4502212088594106"/>
      <inertia ixx="0.001685" iyy="0.00255" izz="0.002528" ixy="-0.0" iyz="2e-06" ixz="-0.0"/>
    </inertial>
    <visual>
      <origin xyz="0.334479 0.026956 -0.602109" rpy="0 0 0"/>
      <geometry>
        <mesh filename="package://conbime_ver1_description/meshes/Robotic_Arm_ver1_2urdf_Component6_v1_1.stl" scale="0.001 0.001 0.001"/>
      </geometry>
      <material name="silver"/>
    </visual>
    <collision>
      <origin xyz="0.334479 0.026956 -0.602109" rpy="0 0 0"/>
      <geometry>
        <mesh filename="package://conbime_ver1_description/meshes/Robotic_Arm_ver1_2urdf_Component6_v1_1.stl" scale="0.001 0.001 0.001"/>
      </geometry>
    </collision>
  </link>
  <link name="Robotic_Arm_ver1_2urdf_Component7_v1_1">
    <inertial>
      <origin xyz="-0.008207251146720884 1.0724226958205851e-07 -1.0867565514161015e-07" rpy="0 0 0"/>
      <mass value="0.631045998433483"/>
      <inertia ixx="0.000333" iyy="0.000302" izz="0.000359" ixy="0.0" iyz="-5e-06" ixz="-0.0"/>
    </inertial>
    <visual>
      <origin xyz="0.438479 0.026956 -0.602109" rpy="0 0 0"/>
      <geometry>
        <mesh filename="package://conbime_ver1_description/meshes/Robotic_Arm_ver1_2urdf_Component7_v1_1.stl" scale="0.001 0.001 0.001"/>
      </geometry>
      <material name="silver"/>
    </visual>
    <collision>
      <origin xyz="0.438479 0.026956 -0.602109" rpy="0 0 0"/>
      <geometry>
        <mesh filename="package://conbime_ver1_description/meshes/Robotic_Arm_ver1_2urdf_Component7_v1_1.stl" scale="0.001 0.001 0.001"/>
      </geometry>
    </collision>
  </link>
  <link name="Robotic_Arm_ver1_2urdf_Component8_v1_1">
    <inertial>
      <origin xyz="0.019057080834595952 -0.025186074755067803 -0.003199260230019152" rpy="0 0 0"/>
      <mass value="0.17302061542980338"/>
      <inertia ixx="0.000109" iyy="2e-05" izz="0.00012" ixy="3.2e-05" iyz="-9e-06" ixz="3e-06"/>
    </inertial>
    <visual>
      <origin xyz="0.461371 0.06761 -0.598552" rpy="0 0 0"/>
      <geometry>
        <mesh filename="package://conbime_ver1_description/meshes/Robotic_Arm_ver1_2urdf_Component8_v1_1.stl" scale="0.001 0.001 0.001"/>
      </geometry>
      <material name="silver"/>
    </visual>
    <collision>
      <origin xyz="0.461371 0.06761 -0.598552" rpy="0 0 0"/>
      <geometry>
        <mesh filename="package://conbime_ver1_description/meshes/Robotic_Arm_ver1_2urdf_Component8_v1_1.stl" scale="0.001 0.001 0.001"/>
      </geometry>
    </collision>
  </link>
  <link name="Robotic_Arm_ver1_2urdf_Component8_v1__1__1">
    <inertial>
      <origin xyz="0.019021962261610736 0.025124486149085037 0.003193621578866379" rpy="0 0 0"/>
      <mass value="0.17302028685492585"/>
      <inertia ixx="0.000109" iyy="2e-05" izz="0.00012" ixy="-3.1e-05" iyz="-9e-06" ixz="-3e-06"/>
    </inertial>
    <visual>
      <origin xyz="0.461371 -0.013698 -0.605666" rpy="0 0 0"/>
      <geometry>
        <mesh filename="package://conbime_ver1_description/meshes/Robotic_Arm_ver1_2urdf_Component8_v1__1__1.stl" scale="0.001 0.001 0.001"/>
      </geometry>
      <material name="silver"/>
    </visual>
    <collision>
      <origin xyz="0.461371 -0.013698 -0.605666" rpy="0 0 0"/>
      <geometry>
        <mesh filename="package://conbime_ver1_description/meshes/Robotic_Arm_ver1_2urdf_Component8_v1__1__1.stl" scale="0.001 0.001 0.001"/>
      </geometry>
    </collision>
  </link>
  <joint name="Revolute 1" type="continuous">
    <origin xyz="0.0 0.0 0.104" rpy="0 0 0"/>
    <parent link="base_link"/>
    <child link="Robotic_Arm_ver1_2urdf_Component2_v1_1"/>
    <axis xyz="0.0 0.0 1.0"/>
  </joint>
  <joint name="Revolute 2" type="continuous">
    <origin xyz="-0.15 0.0 0.15" rpy="0 0 0"/>
    <parent link="Robotic_Arm_ver1_2urdf_Component2_v1_1"/>
    <child link="Robotic_Arm_ver1_2urdf_Component3_v1_1"/>
    <axis xyz="0.0 1.0 -0.0"/>
  </joint>
  <joint name="Revolute 3" type="continuous">
    <origin xyz="0.175 0.0 0.303109" rpy="0 0 0"/>
    <parent link="Robotic_Arm_ver1_2urdf_Component3_v1_1"/>
    <child link="Robotic_Arm_ver1_2urdf_Component4_v1_1"/>
    <axis xyz="0.0 -1.0 0.0"/>
  </joint>
  <joint name="Revolute 5" type="continuous">
    <origin xyz="-0.201 -0.026956 0.045" rpy="0 0 0"/>
    <parent link="Robotic_Arm_ver1_2urdf_Component4_v1_1"/>
    <child link="Robotic_Arm_ver1_2urdf_Component5_v1_1"/>
    <axis xyz="-1.0 -0.0 0.0"/>
  </joint>
  <joint name="Revolute 6" type="continuous">
    <origin xyz="-0.158479 0.0 0.0" rpy="0 0 0"/>
    <parent link="Robotic_Arm_ver1_2urdf_Component5_v1_1"/>
    <child link="Robotic_Arm_ver1_2urdf_Component6_v1_1"/>
    <axis xyz="0.0 0.996195 0.087156"/>
  </joint>
  <joint name="Revolute 7" type="continuous">
    <origin xyz="-0.104 0.0 0.0" rpy="0 0 0"/>
    <parent link="Robotic_Arm_ver1_2urdf_Component6_v1_1"/>
    <child link="Robotic_Arm_ver1_2urdf_Component7_v1_1"/>
    <axis xyz="-1.0 0.0 -0.0"/>
  </joint>
  <joint name="Revolute 10" type="continuous">
    <origin xyz="-0.022892 -0.040654 -0.003557" rpy="0 0 0"/>
    <parent link="Robotic_Arm_ver1_2urdf_Component7_v1_1"/>
    <child link="Robotic_Arm_ver1_2urdf_Component8_v1_1"/>
    <axis xyz="-0.0 -0.087156 0.996195"/>
  </joint>
  <joint name="Revolute 11" type="continuous">
    <origin xyz="-0.022892 0.040654 0.003557" rpy="0 0 0"/>
    <parent link="Robotic_Arm_ver1_2urdf_Component7_v1_1"/>
    <child link="Robotic_Arm_ver1_2urdf_Component8_v1__1__1"/>
    <axis xyz="-0.0 -0.087156 0.996195"/>
  </joint>
</robot>
